Workbook
Name Slicer_Month: #N/A
Name Slicer_Resort: #N/A

Sheet 2026 Payment Summary

Sheet Pivots_Backend
A1: Collection by Resort
A2: Resort | B2: Total Invoice | C2: Total Room Revenue | D2: Deposit Received | E2: Balance (Final Invoice)
A3: (blank)
A4: Resort 1 | B4: 15729669 | C4: 8152194.4 | D4: 5133921.8 | E4: 10603621
A5: Resort 2 | B5: 11586880 | C5: 6380161.8 | D5: 2984393.8 | E5: 8615913.2
A6: Resort 3 | B6: 2006000 | D6: 862637.57 | E6: 1143362.5
A7: Grand Total | B7: 29322548 | C7: 14532356 | D7: 8980953.1 | E7: 20362897
A11: Month | B11: (All) | D11: Month | E11: (All)
A13: Country | B13: Invoice Percentage | D13: Payment Status | E13: Sum of Invoice Amount
A14: UNITED KINGDOM | B14: 0.2363008 | D14: Not paid yet | E14: 13520991
A15: United States | B15: 0.11350125 | D15: Deposit Paid | E15: 8432884.8
A16: Germany | B16: 0.082200773 | D16: Fully Paid | E16: 6227911.3
A17: Russia | B17: 0.076275606 | D17: Credit facility | E17: 589432.94
A18: China | B18: 0.071997551 | D18: Against VCC | E18: 487764.13
A19: Switzerland | B19: 0.04038381 | D19: (blank) | E19: 30773.28
A20: Denmark | B20: 0.038771698 | D20: Payment on Arrival | E20: 19329
A21: Australia | B21: 0.037696999 | D21: Comp | E21: 13461.68
A22: United Arab Emirates | B22: 0.028594582 | D22: Tentative | E22: 0
A23: Unknown | B23: 0.026354 | D23: Grand Total | E23: 29322548
A24: Japan | B24: 0.020616291
A25: Austria | B25: 0.018817522
A26: Singapore | B26: 0.018544649
A27: Sweden | B27: 0.016808676
A28: Italy | B28: 0.016435078 | D28: Month | E28: (All)
A29: Spain | B29: 0.015615795
A30: (blank) | B30: 0.012285495 | D30: Deposit/Full | E30: Sum of Invoice Amount
A31: France | B31: 0.010643585 | D31: Deposit | E31: 22959656
A32: Brazil | B32: 0.0094251249 | D32: Full Payment | E32: 6362892
A33: Chinese Taiwan | B33: 0.0087272183 | D33: Grand Total | E33: 29322548
A34: Argentina | B34: 0.0078760918
A35: Netherlands | B35: 0.00750874
A36: Finland | B36: 0.0071381041
A37: Turkey | B37: 0.0068708947
A38: Kazakhstan | B38: 0.0063839097 | D38: Month | E38: (All)
A39: Ukraine | B39: 0.0051743852
A40: India | B40: 0.0047798472 | D40: Country | E40: Invoice Percentage
A41: Saudi Arabia | B41: 0.0047457335 | D41: UNITED KINGDOM | E41: 0.31419759
A42: Bermuda | B42: 0.0047341714 | D42: United States | E42: 0.15091704
A43: Korea (South) | B43: 0.004714769 | D43: Germany | E43: 0.10929834
A44: Thailand | B44: 0.0041502853 | D44: Russia | E44: 0.10141993
...

Sheet Dashboard_Data
A1: Collection by Resort
A2: Resort | B2: Total Invoice | C2: Total Room Revenue | D2: Deposit Received | E2: Balance (Final Invoice)
A3: Resort 1 | B3: =IFERROR(GETPIVOTDATA("Total Invoice",Pivots_Backend!$A$2,"Resort",$A3),0) -> 15729669 | C3: =IFERROR(GETPIVOTDATA("Total Room Revenue",Pivots_Backend!$A$2,"Resort",$A3),0) -> 8152194.4 | D3: =IFERROR(GETPIVOTDATA("Deposit Received",Pivots_Backend!$A$2,"Resort",$A3),0) -> 5133921.8 | E3: =IFERROR(GETPIVOTDATA("Balance (Final Invoice)",Pivots_Backend!$A$2,"Resort",$A3),0) -> 10603621
A4: Resort 2 | B4: =IFERROR(GETPIVOTDATA("Total Invoice",Pivots_Backend!$A$2,"Resort",$A4),0) -> 11586880 | C4: =IFERROR(GETPIVOTDATA("Total Room Revenue",Pivots_Backend!$A$2,"Resort",$A4),0) -> 6380161.8 | D4: =IFERROR(GETPIVOTDATA("Deposit Received",Pivots_Backend!$A$2,"Resort",$A4),0) -> 2984393.8 | E4: =IFERROR(GETPIVOTDATA("Balance (Final Invoice)",Pivots_Backend!$A$2,"Resort",$A4),0) -> 8615913.2
A5: Resort 3 | B5: =IFERROR(GETPIVOTDATA("Total Invoice",Pivots_Backend!$A$2,"Resort",$A5),0) -> 2006000 | C5: =IFERROR(GETPIVOTDATA("Total Room Revenue",Pivots_Backend!$A$2,"Resort",$A5),0) -> 0 | D5: =IFERROR(GETPIVOTDATA("Deposit Received",Pivots_Backend!$A$2,"Resort",$A5),0) -> 862637.57 | E5: =IFERROR(GETPIVOTDATA("Balance (Final Invoice)",Pivots_Backend!$A$2,"Resort",$A5),0) -> 1143362.5
A6: Grand Total | B6: =IFERROR(GETPIVOTDATA("Total Invoice",Pivots_Backend!$A$2),0) -> 29322548 | C6: =IFERROR(GETPIVOTDATA("Total Room Revenue",Pivots_Backend!$A$2),0) -> 14532356 | D6: =IFERROR(GETPIVOTDATA("Deposit Received",Pivots_Backend!$A$2),0) -> 8980953.1 | E6: =IFERROR(GETPIVOTDATA("Balance (Final Invoice)",Pivots_Backend!$A$2),0) -> 20362897

Sheet Data_Consolidated
A1: Resort | B1: Due Date | C1: Invoice Amount | D1: Payment Received | E1: Balance | F1: Payment Status | G1: Arrival | H1: Departure | I1: No of nights | J1: Month | K1: Month Number | L1: Year | M1: Payment Type | N1: Room Revenue | O1: Date Entered | P1: Country
A2: Resort 1 | B2: 90 days pta | C2: 199999.97 | D2: 199999.97 | F2: Fully Paid | G2: 46023 | H2: 46030 | I2: 7 | J2: =TEXT(tblPayments[[#This Row],[Arrival]],"mmm") -> Jan | K2: =MONTH(tblPayments[[#This Row],[Arrival]]) -> 1 | L2: =YEAR(tblPayments[[#This Row],[Arrival]]) -> 2026 | M2: =IF(tblPayments[[#This Row],[Balance]]=0,"Full Payment","Deposit") -> Full Payment | N2: 137553.57 | O2: 45933 | P2: Russia
A3: Resort 1 | B3: 90 days pta | C3: 209974.09 | D3: 209974.09 | F3: Fully Paid | G3: 46023 | H3: 46030 | I3: 7 | J3: =TEXT(tblPayments[[#This Row],[Arrival]],"mmm") -> Jan | K3: =MONTH(tblPayments[[#This Row],[Arrival]]) -> 1 | L3: =YEAR(tblPayments[[#This Row],[Arrival]]) -> 2026 | M3: =IF(tblPayments[[#This Row],[Balance]]=0,"Full Payment","Deposit") -> Full Payment | N3: 149217.09 | O3: 45861 | P3: UNITED KINGDOM
A4: Resort 1 | B4: 90 days pta | C4: 136440 | D4: 136440 | F4: Fully Paid | G4: 46024 | H4: 46034 | I4: 10 | J4: =TEXT(tblPayments[[#This Row],[Arrival]],"mmm") -> Jan | K4: =MONTH(tblPayments[[#This Row],[Arrival]]) -> 1 | L4: =YEAR(tblPayments[[#This Row],[Arrival]]) -> 2026 | M4: =IF(tblPayments[[#This Row],[Balance]]=0,"Full Payment","Deposit") -> Full Payment | N4: 95268.04 | O4: 45895 | P4: Russia
A5: Resort 1 | B5: 90 days pta | C5: 131512 | D5: 131512 | F5: Fully Paid | G5: 46024 | H5: 46033 | I5: 9 | J5: =TEXT(tblPayments[[#This Row],[Arrival]],"mmm") -> Jan | K5: =MONTH(tblPayments[[#This Row],[Arrival]]) -> 1 | L5: =YEAR(tblPayments[[#This Row],[Arrival]]) -> 2026 | M5: =IF(tblPayments[[#This Row],[Balance]]=0,"Full Payment","Deposit") -> Full Payment | N5: 90370.98 | O5: 45973 | P5: Russia
A6: Resort 1 | B6: 90 days pta | C6: 65778 | D6: 65778 | F6: Fully Paid | G6: 46025 | H6: 46032 | I6: 7 | J6: =TEXT(tblPayments[[#This Row],[Arrival]],"mmm") -> Jan | K6: =MONTH(tblPayments[[#This Row],[Arrival]]) -> 1 | L6: =YEAR(tblPayments[[#This Row],[Arrival]]) -> 2026 | M6: =IF(tblPayments[[#This Row],[Balance]]=0,"Full Payment","Deposit") -> Full Payment | N6: 36985.27 | O6: 45736 | P6: UNITED KINGDOM
A7: Resort 1 | B7: 90 days pta | C7: 116300 | D7: 116300 | F7: Fully Paid | G7: 46025 | H7: 46034 | I7: 9 | J7: =TEXT(tblPayments[[#This Row],[Arrival]],"mmm") -> Jan | K7: =MONTH(tblPayments[[#This Row],[Arrival]]) -> 1 | L7: =YEAR(tblPayments[[#This Row],[Arrival]]) -> 2026 | M7: =IF(tblPayments[[#This Row],[Balance]]=0,"Full Payment","Deposit") -> Full Payment | N7: 84335.67 | O7: 45901 | P7: Russia
A8: Resort 1 | B8: 90 days pta | C8: 78492.39 | D8: 78824.54 | F8: Fully Paid | G8: 46025 | H8: 46032 | I8: 7 | J8: =TEXT(tblPayments[[#This Row],[Arrival]],"mmm") -> Jan | K8: =MONTH(tblPayments[[#This Row],[Arrival]]) -> 1 | L8: =YEAR(tblPayments[[#This Row],[Arrival]]) -> 2026 | M8: =IF(tblPayments[[#This Row],[Balance]]=0,"Full Payment","Deposit") -> Full Payment | N8: 57379.84 | O8: 45833 | P8: Russia
A9: Resort 1 | B9: 90 days pta | C9: 20030.88 | D9: 20030.88 | F9: Fully Paid | G9: 46026 | H9: 46030 | I9: 4 | J9: =TEXT(tblPayments[[#This Row],[Arrival]],"mmm") -> Jan | K9: =MONTH(tblPayments[[#This Row],[Arrival]]) -> 1 | L9: =YEAR(tblPayments[[#This Row],[Arrival]]) -> 2026 | M9: =IF(tblPayments[[#This Row],[Balance]]=0,"Full Payment","Deposit") -> Full Payment | N9: 11604.76 | O9: 45912 | P9: India
A10: Resort 1 | B10: 90 days pta | C10: 85106 | D10: 85106 | F10: Fully Paid | G10: 46026 | H10: 46031 | I10: 5 | J10: =TEXT(tblPayments[[#This Row],[Arrival]],"mmm") -> Jan | K10: =MONTH(tblPayments[[#This Row],[Arrival]]) -> 1 | L10: =YEAR(tblPayments[[#This Row],[Arrival]]) -> 2026 | M10: =IF(tblPayments[[#This Row],[Balance]]=0,"Full Payment","Deposit") -> Full Payment | N10: 59803.1 | O10: 45933 | P10: Greece
A11: Resort 1 | B11: 90 days pta | C11: 0 | D11: 0 | F11: Comp | G11: 46026 | H11: 46028 | I11: 2 | J11: =TEXT(tblPayments[[#This Row],[Arrival]],"mmm") -> Jan | K11: =MONTH(tblPayments[[#This Row],[Arrival]]) -> 1 | L11: =YEAR(tblPayments[[#This Row],[Arrival]]) -> 2026 | M11: =IF(tblPayments[[#This Row],[Balance]]=0,"Full Payment","Deposit") -> Full Payment | N11: 0 | O11: 45973 | P11: Thailand
A12: Resort 1 | B12: 90 days pta | C12: 0 | D12: 0 | F12: Tentative | G12: 46026 | H12: 46033 | I12: 7 | J12: =TEXT(tblPayments[[#This Row],[Arrival]],"mmm") -> Jan | K12: =MONTH(tblPayments[[#This Row],[Arrival]]) -> 1 | L12: =YEAR(tblPayments[[#This Row],[Arrival]]) -> 2026 | M12: =IF(tblPayments[[#This Row],[Balance]]=0,"Full Payment","Deposit") -> Full Payment | N12: 22696.94 | O12: 46001 | P12: Unknown
A13: Resort 1 | B13: 90 days pta | C13: 0 | D13: 0 | F13: Tentative | G13: 46026 | H13: 46033 | I13: 7 | J13: =TEXT(tblPayments[[#This Row],[Arrival]],"mmm") -> Jan | K13: =MONTH(tblPayments[[#This Row],[Arrival]]) -> 1 | L13: =YEAR(tblPayments[[#This Row],[Arrival]]) -> 2026 | M13: =IF(tblPayments[[#This Row],[Balance]]=0,"Full Payment","Deposit") -> Full Payment | N13: 22696.94 | O13: 46001 | P13: Unknown
A14: Resort 1 | B14: 90 days pta | C14: 18682.88 | D14: 18682.88 | F14: Fully Paid | G14: 46026 | H14: 46030 | I14: 4 | J14: =TEXT(tblPayments[[#This Row],[Arrival]],"mmm") -> Jan | K14: =MONTH(tblPayments[[#This Row],[Arrival]]) -> 1 | L14: =YEAR(tblPayments[[#This Row],[Arrival]]) -> 2026 | M14: =IF(tblPayments[[#This Row],[Balance]]=0,"Full Payment","Deposit") -> Full Payment | N14: 11766.56 | O14: 45837 | P14: Unknown
A15: Resort 1 | B15: 90 days pta | C15: 63049.9 | D15: 2600 | E15: 60449.9 | F15: Against VCC | G15: 46027 | H15: 46036 | I15: 9 | J15: =TEXT(tblPayments[[#This Row],[Arrival]],"mmm") -> Jan | K15: =MONTH(tblPayments[[#This Row],[Arrival]]) -> 1 | L15: =YEAR(tblPayments[[#This Row],[Arrival]]) -> 2026 | M15: =IF(tblPayments[[#This Row],[Balance]]=0,"Full Payment","Deposit") -> Deposit | N15: 45073.17 | O15: 45938 | P15: France
A16: Resort 1 | B16: 90 days pta | C16: 43204 | D16: 43204 | F16: Fully Paid | G16: 46027 | H16: 46033 | I16: 6 | J16: =TEXT(tblPayments[[#This Row],[Arrival]],"mmm") -> Jan | K16: =MONTH(tblPayments[[#This Row],[Arrival]]) -> 1 | L16: =YEAR(tblPayments[[#This Row],[Arrival]]) -> 2026 | M16: =IF(tblPayments[[#This Row],[Balance]]=0,"Full Payment","Deposit") -> Full Payment | N16: 30396.3 | O16: 45975 | P16: Germany
A17: Resort 1 | B17: 90 days pta | C17: 30367.55 | D17: 30367.55 | F17: Fully Paid | G17: 46027 | H17: 46030 | I17: 3 | J17: =TEXT(tblPayments[[#This Row],[Arrival]],"mmm") -> Jan | K17: =MONTH(tblPayments[[#This Row],[Arrival]]) -> 1 | L17: =YEAR(tblPayments[[#This Row],[Arrival]]) -> 2026 | M17: =IF(tblPayments[[#This Row],[Balance]]=0,"Full Payment","Deposit") -> Full Payment | N17: 21402.3 | O17: 45961 | P17: Japan
A18: Resort 1 | B18: 90 days pta | C18: 56372.1 | D18: 56372.1 | F18: Deposit Paid | G18: 46028 | H18: 46035 | I18: 7 | J18: =TEXT(tblPayments[[#This Row],[Arrival]],"mmm") -> Jan | K18: =MONTH(tblPayments[[#This Row],[Arrival]]) -> 1 | L18: =YEAR(tblPayments[[#This Row],[Arrival]]) -> 2026 | M18: =IF(tblPayments[[#This Row],[Balance]]=0,"Full Payment","Deposit") -> Full Payment | N18: 38085.53 | O18: 45976 | P18: Russia
A19: Resort 1 | B19: 90 days pta | C19: 0 | D19: 0 | F19: Comp | G19: 46028 | H19: 46033 | I19: 5 | J19: =TEXT(tblPayments[[#This Row],[Arrival]],"mmm") -> Jan | K19: =MONTH(tblPayments[[#This Row],[Arrival]]) -> 1 | L19: =YEAR(tblPayments[[#This Row],[Arrival]]) -> 2026 | M19: =IF(tblPayments[[#This Row],[Balance]]=0,"Full Payment","Deposit") -> Full Payment | N19: 0 | O19: 45975 | P19: Russia
A20: Resort 1 | B20: 90 days pta | F20: Comp | G20: 46029 | H20: 46036 | I20: 7 | J20: =TEXT(tblPayments[[#This Row],[Arrival]],"mmm") -> Jan | K20: =MONTH(tblPayments[[#This Row],[Arrival]]) -> 1 | L20: =YEAR(tblPayments[[#This Row],[Arrival]]) -> 2026 | M20: =IF(tblPayments[[#This Row],[Balance]]=0,"Full Payment","Deposit") -> Full Payment | N20: 10040.38
A21: Resort 1 | B21: 90 days pta | C21: 19000 | D21: 11017.78 | E21: 7982.22 | F21: Deposit Paid | G21: 46029 | H21: 46045 | I21: 16 | J21: =TEXT(tblPayments[[#This Row],[Arrival]],"mmm") -> Jan | K21: =MONTH(tblPayments[[#This Row],[Arrival]]) -> 1 | L21: =YEAR(tblPayments[[#This Row],[Arrival]]) -> 2026 | M21: =IF(tblPayments[[#This Row],[Balance]]=0,"Full Payment","Deposit") -> Deposit | N21: 0 | O21: 45743 | P21: Switzerland
A22: Resort 1 | B22: 90 days pta | C22: 52368.8 | E22: 52368.8 | F22: Not paid yet | G22: 46030 | H22: 46037 | I22: 7 | J22: =TEXT(tblPayments[[#This Row],[Arrival]],"mmm") -> Jan | K22: =MONTH(tblPayments[[#This Row],[Arrival]]) -> 1 | L22: =YEAR(tblPayments[[#This Row],[Arrival]]) -> 2026 | M22: =IF(tblPayments[[#This Row],[Balance]]=0,"Full Payment","Deposit") -> Deposit | N22: 37832.76 | O22: 45995 | P22: Kuwait
A23: Resort 1 | B23: 90 days pta | F23: Tentative | G23: 46030 | H23: 46046 | I23: 16 | J23: =TEXT(tblPayments[[#This Row],[Arrival]],"mmm") -> Jan | K23: =MONTH(tblPayments[[#This Row],[Arrival]]) -> 1 | L23: =YEAR(tblPayments[[#This Row],[Arrival]]) -> 2026 | M23: =IF(tblPayments[[#This Row],[Balance]]=0,"Full Payment","Deposit") -> Full Payment | N23: 10622.68 | O23: 45932 | P23: Switzerland
A24: Resort 1 | B24: 90 days pta | C24: 0 | D24: 0 | F24: Comp | G24: 46031 | H24: 46038 | I24: 7 | J24: =TEXT(tblPayments[[#This Row],[Arrival]],"mmm") -> Jan | K24: =MONTH(tblPayments[[#This Row],[Arrival]]) -> 1 | L24: =YEAR(tblPayments[[#This Row],[Arrival]]) -> 2026 | M24: =IF(tblPayments[[#This Row],[Balance]]=0,"Full Payment","Deposit") -> Full Payment | N24: 0 | O24: 45674 | P24: UNITED KINGDOM
A25: Resort 1 | B25: 90 days pta | C25: 67954.74 | D25: 67954.74 | F25: Fully Paid | G25: 46031 | H25: 46039 | I25: 8 | J25: =TEXT(tblPayments[[#This Row],[Arrival]],"mmm") -> Jan | K25: =MONTH(tblPayments[[#This Row],[Arrival]]) -> 1 | L25: =YEAR(tblPayments[[#This Row],[Arrival]]) -> 2026 | M25: =IF(tblPayments[[#This Row],[Balance]]=0,"Full Payment","Deposit") -> Full Payment | N25: 49406.1 | O25: 45980 | P25: Argentina
A26: Resort 1 | B26: 90 days pta | C26: 157003.12 | D26: 157003.12 | F26: Fully Paid | G26: 46032 | H26: 46040 | I26: 8 | J26: =TEXT(tblPayments[[#This Row],[Arrival]],"mmm") -> Jan | K26: =MONTH(tblPayments[[#This Row],[Arrival]]) -> 1 | L26: =YEAR(tblPayments[[#This Row],[Arrival]]) -> 2026 | M26: =IF(tblPayments[[#This Row],[Balance]]=0,"Full Payment","Deposit") -> Full Payment | N26: 107244.08 | O26: 45792 | P26: Finland
A27: Resort 1 | B27: 30 days pta | C27: 33897 | D27: 33897 | F27: Fully Paid | G27: 46034 | H27: 46040 | I27: 6 | J27: =TEXT(tblPayments[[#This Row],[Arrival]],"mmm") -> Jan | K27: =MONTH(tblPayments[[#This Row],[Arrival]]) -> 1 | L27: =YEAR(tblPayments[[#This Row],[Arrival]]) -> 2026 | M27: =IF(tblPayments[[#This Row],[Balance]]=0,"Full Payment","Deposit") -> Full Payment | N27: 20535.72 | O27: 45966 | P27: Russia
A28: Resort 1 | B28: 30 days pta | C28: 41700 | D28: 41700 | F28: Fully Paid | G28: 46034 | H28: 46043 | I28: 9 | J28: =TEXT(tblPayments[[#This Row],[Arrival]],"mmm") -> Jan | K28: =MONTH(tblPayments[[#This Row],[Arrival]]) -> 1 | L28: =YEAR(tblPayments[[#This Row],[Arrival]]) -> 2026 | M28: =IF(tblPayments[[#This Row],[Balance]]=0,"Full Payment","Deposit") -> Full Payment | N28: 10003.08 | O28: 45911 | P28: Sweden
A29: Resort 1 | B29: 30 days pta | C29: 58243.22 | E29: 58243.22 | F29: Not paid yet | G29: 46034 | H29: 46048 | I29: 14 | J29: =TEXT(tblPayments[[#This Row],[Arrival]],"mmm") -> Jan | K29: =MONTH(tblPayments[[#This Row],[Arrival]]) -> 1 | L29: =YEAR(tblPayments[[#This Row],[Arrival]]) -> 2026 | M29: =IF(tblPayments[[#This Row],[Balance]]=0,"Full Payment","Deposit") -> Deposit | N29: 34161.12 | O29: 45777 | P29: Sweden
A30: Resort 1 | B30: 30 days pta | F30: Tentative | G30: 46034 | H30: 46038 | I30: 4 | J30: =TEXT(tblPayments[[#This Row],[Arrival]],"mmm") -> Jan | K30: =MONTH(tblPayments[[#This Row],[Arrival]]) -> 1 | L30: =YEAR(tblPayments[[#This Row],[Arrival]]) -> 2026 | M30: =IF(tblPayments[[#This Row],[Balance]]=0,"Full Payment","Deposit") -> Full Payment | O30: 46002
A31: Resort 1 | B31: 30 days pta | C31: 29085 | E31: 29085 | F31: Not paid yet | G31: 46035 | H31: 46040 | I31: 5 | J31: =TEXT(tblPayments[[#This Row],[Arrival]],"mmm") -> Jan | K31: =MONTH(tblPayments[[#This Row],[Arrival]]) -> 1 | L31: =YEAR(tblPayments[[#This Row],[Arrival]]) -> 2026 | M31: =IF(tblPayments[[#This Row],[Balance]]=0,"Full Payment","Deposit") -> Deposit | N31: 19570.7 | O31: 45998 | P31: Switzerland
A32: Resort 1 | B32: 30 days pta | C32: 43861.8 | D32: 18861.8 | E32: 25000 | F32: Deposit Paid | G32: 46035 | H32: 46041 | I32: 6 | J32: =TEXT(tblPayments[[#This Row],[Arrival]],"mmm") -> Jan | K32: =MONTH(tblPayments[[#This Row],[Arrival]]) -> 1 | L32: =YEAR(tblPayments[[#This Row],[Arrival]]) -> 2026 | M32: =IF(tblPayments[[#This Row],[Balance]]=0,"Full Payment","Deposit") -> Deposit | N32: 32644.74 | O32: 45976 | P32: Russia
A33: Resort 1 | B33: 30 days pta | C33: 127800.88 | D33: 50000 | E33: 77800.88 | F33: Deposit Paid | G33: 46035 | H33: 46049 | I33: 14 | J33: =TEXT(tblPayments[[#This Row],[Arrival]],"mmm") -> Jan | K33: =MONTH(tblPayments[[#This Row],[Arrival]]) -> 1 | L33: =YEAR(tblPayments[[#This Row],[Arrival]]) -> 2026 | M33: =IF(tblPayments[[#This Row],[Balance]]=0,"Full Payment","Deposit") -> Deposit | N33: 88943.12 | O33: 45917 | P33: Russia
A34: Resort 1 | B34: 30 days pta | C34: 103950 | D34: 103950 | F34: Fully Paid | G34: 46035 | H34: 46045 | I34: 10 | J34: =TEXT(tblPayments[[#This Row],[Arrival]],"mmm") -> Jan | K34: =MONTH(tblPayments[[#This Row],[Arrival]]) -> 1 | L34: =YEAR(tblPayments[[#This Row],[Arrival]]) -> 2026 | M34: =IF(tblPayments[[#This Row],[Balance]]=0,"Full Payment","Deposit") -> Full Payment | N34: 0 | O34: 45555 | P34: United States
A35: Resort 1 | B35: 30 days pta | C35: 91560 | E35: 91560 | F35: Not paid yet | G35: 46036 | H35: 46066 | I35: 30 | J35: =TEXT(tblPayments[[#This Row],[Arrival]],"mmm") -> Jan | K35: =MONTH(tblPayments[[#This Row],[Arrival]]) -> 1 | L35: =YEAR(tblPayments[[#This Row],[Arrival]]) -> 2026 | M35: =IF(tblPayments[[#This Row],[Balance]]=0,"Full Payment","Deposit") -> Deposit | N35: 47179.5 | O35: 45776 | P35: Denmark
A36: Resort 1 | B36: 30 days pta | C36: 136400.34 | E36: 136400.34 | F36: Not paid yet | G36: 46036 | H36: 46054 | I36: 18 | J36: =TEXT(tblPayments[[#This Row],[Arrival]],"mmm") -> Jan | K36: =MONTH(tblPayments[[#This Row],[Arrival]]) -> 1 | L36: =YEAR(tblPayments[[#This Row],[Arrival]]) -> 2026 | M36: =IF(tblPayments[[#This Row],[Balance]]=0,"Full Payment","Deposit") -> Deposit | N36: 87639.12 | O36: 45861 | P36: Argentina
A37: Resort 1 | B37: 30 days pta | F37: Tentative | G37: 46037 | H37: 46046 | I37: 9 | J37: =TEXT(tblPayments[[#This Row],[Arrival]],"mmm") -> Jan | K37: =MONTH(tblPayments[[#This Row],[Arrival]]) -> 1 | L37: =YEAR(tblPayments[[#This Row],[Arrival]]) -> 2026 | M37: =IF(tblPayments[[#This Row],[Balance]]=0,"Full Payment","Deposit") -> Full Payment | N37: 0 | O37: 45912 | P37: Russia
A38: Resort 1 | B38: 30 days pta | C38: 33970 | D38: 33970 | F38: Fully Paid | G38: 46038 | H38: 46053 | I38: 15 | J38: =TEXT(tblPayments[[#This Row],[Arrival]],"mmm") -> Jan | K38: =MONTH(tblPayments[[#This Row],[Arrival]]) -> 1 | L38: =YEAR(tblPayments[[#This Row],[Arrival]]) -> 2026 | M38: =IF(tblPayments[[#This Row],[Balance]]=0,"Full Payment","Deposit") -> Full Payment | N38: 12213.9 | O38: 45341 | P38: Turkey
A39: Resort 1 | B39: 30 days pta | C39: 83115.1 | E39: 83115.1 | F39: Not paid yet | G39: 46038 | H39: 46044 | I39: 6 | J39: =TEXT(tblPayments[[#This Row],[Arrival]],"mmm") -> Jan | K39: =MONTH(tblPayments[[#This Row],[Arrival]]) -> 1 | L39: =YEAR(tblPayments[[#This Row],[Arrival]]) -> 2026 | M39: =IF(tblPayments[[#This Row],[Balance]]=0,"Full Payment","Deposit") -> Deposit | N39: 52936.44 | O39: 45870 | P39: United States
A40: Resort 1 | B40: 30 days pta | C40: 22025 | E40: 22025 | F40: Not paid yet | G40: 46038 | H40: 46045 | I40: 7 | J40: =TEXT(tblPayments[[#This Row],[Arrival]],"mmm") -> Jan | K40: =MONTH(tblPayments[[#This Row],[Arrival]]) -> 1 | L40: =YEAR(tblPayments[[#This Row],[Arrival]]) -> 2026 | M40: =IF(tblPayments[[#This Row],[Balance]]=0,"Full Payment","Deposit") -> Deposit | N40: 0 | O40: 45989 | P40: Denmark
...

Sheet Resort 1
A1: Resort | B1: Due Date | C1: Invoice Amount | D1: Payment Received | E1: Balance | F1: Payment Status | G1: Arrival | H1: Departure | I1: No of nights | J1: Room Revenue | K1: Date Entered | L1: Country
A2: Resort 1 | B2: 90 days pta | C2: 199999.97 | D2: 199999.97 | F2: Fully Paid | G2: 46023 | H2: 46030 | I2: 7 | J2: 137553.57 | K2: 45933 | L2: Russia
A3: Resort 1 | B3: 90 days pta | C3: 209974.09 | D3: 209974.09 | F3: Fully Paid | G3: 46023 | H3: 46030 | I3: 7 | J3: 149217.09 | K3: 45861 | L3: UNITED KINGDOM
A4: Resort 1 | B4: 90 days pta | C4: 136440 | D4: 136440 | F4: Fully Paid | G4: 46024 | H4: 46034 | I4: 10 | J4: 95268.04 | K4: 45895 | L4: Russia
A5: Resort 1 | B5: 90 days pta | C5: 131512 | D5: 131512 | F5: Fully Paid | G5: 46024 | H5: 46033 | I5: 9 | J5: 90370.98 | K5: 45973 | L5: Russia
A6: Resort 1 | B6: 90 days pta | C6: 65778 | D6: 65778 | F6: Fully Paid | G6: 46025 | H6: 46032 | I6: 7 | J6: 36985.27 | K6: 45736 | L6: UNITED KINGDOM
A7: Resort 1 | B7: 90 days pta | C7: 116300 | D7: 116300 | F7: Fully Paid | G7: 46025 | H7: 46034 | I7: 9 | J7: 84335.67 | K7: 45901 | L7: Russia
A8: Resort 1 | B8: 90 days pta | C8: 78492.39 | D8: 78824.54 | F8: Fully Paid | G8: 46025 | H8: 46032 | I8: 7 | J8: 57379.84 | K8: 45833 | L8: Russia
A9: Resort 1 | B9: 90 days pta | C9: 20030.88 | D9: 20030.88 | F9: Fully Paid | G9: 46026 | H9: 46030 | I9: 4 | J9: 11604.76 | K9: 45912 | L9: India
A10: Resort 1 | B10: 90 days pta | C10: 85106 | D10: 85106 | F10: Fully Paid | G10: 46026 | H10: 46031 | I10: 5 | J10: 59803.1 | K10: 45933 | L10: Greece
A11: Resort 1 | B11: 90 days pta | C11: 0 | D11: 0 | F11: Comp | G11: 46026 | H11: 46028 | I11: 2 | J11: 0 | K11: 45973 | L11: Thailand
A12: Resort 1 | B12: 90 days pta | C12: 0 | D12: 0 | F12: Tentative | G12: 46026 | H12: 46033 | I12: 7 | J12: 22696.94 | K12: 46001 | L12: Unknown
A13: Resort 1 | B13: 90 days pta | C13: 0 | D13: 0 | F13: Tentative | G13: 46026 | H13: 46033 | I13: 7 | J13: 22696.94 | K13: 46001 | L13: Unknown
A14: Resort 1 | B14: 90 days pta | C14: 18682.88 | D14: 18682.88 | F14: Fully Paid | G14: 46026 | H14: 46030 | I14: 4 | J14: 11766.56 | K14: 45837 | L14: Unknown
A15: Resort 1 | B15: 90 days pta | C15: 63049.9 | D15: 2600 | E15: 60449.9 | F15: Against VCC | G15: 46027 | H15: 46036 | I15: 9 | J15: 45073.17 | K15: 45938 | L15: France
A16: Resort 1 | B16: 90 days pta | C16: 43204 | D16: 43204 | F16: Fully Paid | G16: 46027 | H16: 46033 | I16: 6 | J16: 30396.3 | K16: 45975 | L16: Germany
A17: Resort 1 | B17: 90 days pta | C17: 30367.55 | D17: 30367.55 | F17: Fully Paid | G17: 46027 | H17: 46030 | I17: 3 | J17: 21402.3 | K17: 45961 | L17: Japan
A18: Resort 1 | B18: 90 days pta | C18: 56372.1 | D18: 56372.1 | F18: Deposit Paid | G18: 46028 | H18: 46035 | I18: 7 | J18: 38085.53 | K18: 45976 | L18: Russia
A19: Resort 1 | B19: 90 days pta | C19: 0 | D19: 0 | F19: Comp | G19: 46028 | H19: 46033 | I19: 5 | J19: 0 | K19: 45975 | L19: Russia
A20: Resort 1 | B20: 90 days pta | F20: Comp | G20: 46029 | H20: 46036 | I20: 7 | J20: 10040.38
A21: Resort 1 | B21: 90 days pta | C21: 19000 | D21: 11017.78 | E21: 7982.22 | F21: Deposit Paid | G21: 46029 | H21: 46045 | I21: 16 | J21: 0 | K21: 45743 | L21: Switzerland
A22: Resort 1 | B22: 90 days pta | C22: 52368.8 | E22: 52368.8 | F22: Not paid yet | G22: 46030 | H22: 46037 | I22: 7 | J22: 37832.76 | K22: 45995 | L22: Kuwait
A23: Resort 1 | B23: 90 days pta | F23: Tentative | G23: 46030 | H23: 46046 | I23: 16 | J23: 10622.68 | K23: 45932 | L23: Switzerland
A24: Resort 1 | B24: 90 days pta | C24: 0 | D24: 0 | F24: Comp | G24: 46031 | H24: 46038 | I24: 7 | J24: 0 | K24: 45674 | L24: UNITED KINGDOM
A25: Resort 1 | B25: 90 days pta | C25: 67954.74 | D25: 67954.74 | F25: Fully Paid | G25: 46031 | H25: 46039 | I25: 8 | J25: 49406.1 | K25: 45980 | L25: Argentina
A26: Resort 1 | B26: 90 days pta | C26: 157003.12 | D26: 157003.12 | F26: Fully Paid | G26: 46032 | H26: 46040 | I26: 8 | J26: 107244.08 | K26: 45792 | L26: Finland
A27: Resort 1 | B27: 30 days pta | C27: 33897 | D27: 33897 | F27: Fully Paid | G27: 46034 | H27: 46040 | I27: 6 | J27: 20535.72 | K27: 45966 | L27: Russia
A28: Resort 1 | B28: 30 days pta | C28: 41700 | D28: 41700 | F28: Fully Paid | G28: 46034 | H28: 46043 | I28: 9 | J28: 10003.08 | K28: 45911 | L28: Sweden
A29: Resort 1 | B29: 30 days pta | C29: 58243.22 | E29: 58243.22 | F29: Not paid yet | G29: 46034 | H29: 46048 | I29: 14 | J29: 34161.12 | K29: 45777 | L29: Sweden
A30: Resort 1 | B30: 30 days pta | F30: Tentative | G30: 46034 | H30: 46038 | I30: 4 | K30: 46002
A31: Resort 1 | B31: 30 days pta | C31: 29085 | E31: 29085 | F31: Not paid yet | G31: 46035 | H31: 46040 | I31: 5 | J31: 19570.7 | K31: 45998 | L31: Switzerland
A32: Resort 1 | B32: 30 days pta | C32: 43861.8 | D32: 18861.8 | E32: 25000 | F32: Deposit Paid | G32: 46035 | H32: 46041 | I32: 6 | J32: 32644.74 | K32: 45976 | L32: Russia
A33: Resort 1 | B33: 30 days pta | C33: 127800.88 | D33: 50000 | E33: 77800.88 | F33: Deposit Paid | G33: 46035 | H33: 46049 | I33: 14 | J33: 88943.12 | K33: 45917 | L33: Russia
A34: Resort 1 | B34: 30 days pta | C34: 103950 | D34: 103950 | F34: Fully Paid | G34: 46035 | H34: 46045 | I34: 10 | J34: 0 | K34: 45555 | L34: United States
A35: Resort 1 | B35: 30 days pta | C35: 91560 | E35: 91560 | F35: Not paid yet | G35: 46036 | H35: 46066 | I35: 30 | J35: 47179.5 | K35: 45776 | L35: Denmark
A36: Resort 1 | B36: 30 days pta | C36: 136400.34 | E36: 136400.34 | F36: Not paid yet | G36: 46036 | H36: 46054 | I36: 18 | J36: 87639.12 | K36: 45861 | L36: Argentina
A37: Resort 1 | B37: 30 days pta | F37: Tentative | G37: 46037 | H37: 46046 | I37: 9 | J37: 0 | K37: 45912 | L37: Russia
A38: Resort 1 | B38: 30 days pta | C38: 33970 | D38: 33970 | F38: Fully Paid | G38: 46038 | H38: 46053 | I38: 15 | J38: 12213.9 | K38: 45341 | L38: Turkey
A39: Resort 1 | B39: 30 days pta | C39: 83115.1 | E39: 83115.1 | F39: Not paid yet | G39: 46038 | H39: 46044 | I39: 6 | J39: 52936.44 | K39: 45870 | L39: United States
A40: Resort 1 | B40: 30 days pta | C40: 22025 | E40: 22025 | F40: Not paid yet | G40: 46038 | H40: 46045 | I40: 7 | J40: 0 | K40: 45989 | L40: Denmark
...

Sheet Resort 2
A1: Resort | B1: Due Date | C1: Invoice Amount | D1: Payment Received | E1: Balance | F1: Payment Status | G1: Arrival | H1: Departure | I1: No of nights | J1: Room Revenue | K1: Date Entered | L1: Country
A2: Resort 2 | B2: 90 days pta | C2: 13788.38 | D2: 13788.38 | F2: Fully Paid | G2: 46023 | H2: 46024 | I2: 1 | J2: 7349.19 | K2: 45912 | L2: Japan
A3: Resort 2 | B3: 90 days pta | C3: 96137.6 | D3: 96137.6 | F3: Fully Paid | G3: 46023 | H3: 46027 | I3: 4 | J3: 66161.16 | K3: 45794 | L3: Japan
A4: Resort 2 | B4: 90 days pta | C4: 79580 | D4: 79580 | F4: Fully Paid | G4: 46023 | H4: 46027 | I4: 4 | J4: 48593.64 | K4: 45724 | L4: United States
A5: Resort 2 | B5: 90 days pta | C5: 31054.8 | D5: 31054.8 | F5: Fully Paid | G5: 46024 | H5: 46028 | I5: 4 | J5: 21277.4 | K5: 45699 | L5: United States
A6: Resort 2 | B6: 90 days pta | C6: 142945.63 | D6: 142945.63 | F6: Fully Paid | G6: 46025 | H6: 46032 | I6: 7 | J6: 81000.78 | K6: 45978 | L6: Spain
A7: Resort 2 | B7: 90 days pta | C7: 104286 | D7: 104286 | F7: Fully Paid | G7: 46026 | H7: 46033 | I7: 7 | J7: 76173.3 | K7: 45953 | L7: United States
A8: Resort 2 | B8: 90 days pta | C8: 108000 | D8: 108000 | F8: Fully Paid | G8: 46026 | H8: 46034 | I8: 8 | J8: 77793.28 | K8: 45982 | L8: Russia
A9: Resort 2 | B9: 90 days pta | C9: 64812.48 | D9: 64812.48 | F9: Fully Paid | G9: 46029 | H9: 46033 | I9: 4 | J9: 56040.44 | K9: 45978 | L9: Unknown
A10: Resort 2 | B10: 90 days pta | C10: 100000 | D10: 25187.52 | E10: 74812.487 | F10: Deposit Paid | G10: 46029 | H10: 46033 | I10: 4 | J10: 55927.52 | K10: 45978 | L10: Unknown
A11: Resort 2 | B11: 30 days pta | C11: 34931.98 | D11: 34931.98 | F11: Fully Paid | G11: 46029 | H11: 46036 | I11: 7 | J11: 22855.49 | K11: 45824 | L11: Russia
A12: Resort 2 | B12: 30 days pta | C12: 53611.66 | E12: 53611.66 | F12: Not paid yet | G12: 46029 | H12: 46043 | I12: 14 | J12: 32521.86 | K12: 45999 | L12: UNITED KINGDOM
A13: Resort 2 | B13: 30 days pta | C13: 54341.6 | D13: 54341.6 | F13: Fully Paid | G13: 46029 | H13: 46034 | I13: 5 | J13: 28503.95 | K13: 45938 | L13: Australia
A14: Resort 2 | B14: 30 days pta | C14: 28757.12 | D14: 28757.12 | F14: Fully Paid | G14: 46030 | H14: 46034 | I14: 4 | J14: 20483.16 | K14: 45962 | L14: Japan
A15: Resort 2 | B15: 30 days pta | C15: 44845.14 | D15: 44845.14 | F15: Fully Paid | G15: 46031 | H15: 46038 | I15: 7 | J15: 28744.73 | K15: 45721 | L15: United States
A16: Resort 2 | B16: 30 days pta | C16: 63370.87 | D16: 63370.87 | F16: Fully Paid | G16: 46032 | H16: 46039 | I16: 7 | J16: 42746.34 | K16: 45992 | L16: Brazil
A17: Resort 2 | B17: 30 days pta | C17: 27132 | D17: 27132 | F17: Fully Paid | G17: 46033 | H17: 46038 | I17: 5 | J17: 16744.5 | K17: 45918 | L17: Brazil
A18: Resort 2 | B18: 30 days pta | C18: 19220 | D18: 19220 | F18: Fully Paid | G18: 46033 | H18: 46038 | I18: 5 | J18: 12315.45 | K18: 45947 | L18: Canada
A19: Resort 2 | B19: 30 days pta | C19: 24522.32 | D19: 24522.32 | F19: Fully Paid | G19: 46033 | H19: 46040 | I19: 7 | J19: 15906.81 | K19: 45967 | L19: United States
A20: Resort 2 | B20: 30 days pta | C20: 31975.68 | D20: 31975.68 | F20: Credit Facility | G20: 46033 | H20: 46037 | I20: 4 | J20: 18803.16 | K20: 45919 | L20: UNITED KINGDOM
A21: Resort 2 | B21: 30 days pta | C21: 77066 | E21: 77066 | F21: Not paid yet | G21: 46034 | H21: 46041 | I21: 7 | J21: 53197.48 | K21: 45702 | L21: Australia
A22: Resort 2 | B22: 30 days pta | F22: Tentative | G22: 46034 | H22: 46038 | I22: 4 | J22: 10531.12 | K22: 45998 | L22: China
A23: Resort 2 | B23: 30 days pta | F23: Tentative | G23: 46034 | H23: 46038 | I23: 4 | J23: 10531.12 | K23: 46000 | L23: China
A24: Resort 2 | B24: 30 days pta | C24: 5402.98 | E24: 5402.98 | F24: Against VCC | G24: 46034 | H24: 46035 | I24: 1 | J24: 2021.5 | K24: 45996
A25: Resort 2 | B25: 30 days pta | C25: 92486 | E25: 92486 | F25: Not paid yet | G25: 46034 | H25: 46041 | I25: 7 | J25: 66948.98 | K25: 45654 | L25: Australia
A26: Resort 2 | B26: 30 days pta | C26: 32887.3 | E26: 32887.3 | F26: Not paid yet | G26: 46034 | H26: 46041 | I26: 7 | J26: 22290.31 | K26: 45702 | L26: Australia
A27: Resort 2 | B27: 30 days pta | C27: 32887.25 | E27: 32887.25 | F27: Not paid yet | G27: 46034 | H27: 46041 | I27: 7 | J27: 22290.31 | K27: 45707 | L27: Australia
A28: Resort 2 | B28: 30 days pta | C28: 23719.16 | D28: 23719.16 | F28: Fully Paid | G28: 46035 | H28: 46040 | I28: 5 | J28: 15529.6 | K28: 45986 | L28: France
A29: Resort 2 | B29: 30 days pta | C29: 10491.53 | E29: 10491.53 | F29: Not paid yet | G29: 46035 | H29: 46042 | I29: 7 | J29: 0 | K29: 45895 | L29: Unknown
A30: Resort 2 | B30: 30 days pta | C30: 16044 | D30: 4011 | E30: 12033 | F30: Deposit Paid | G30: 46035 | H30: 46039 | I30: 4 | J30: 7379.42 | K30: 45973 | L30: China
A31: Resort 2 | B31: 30 days pta | C31: 16744 | D31: 4186 | E31: 12558 | F31: Deposit Paid | G31: 46035 | H31: 46039 | I31: 4 | J31: 7913.62 | K31: 45975 | L31: China
A32: Resort 2 | B32: 30 days pta | C32: 12547.66 | E32: 12547.66 | F32: Not paid yet | G32: 46036 | H32: 46038 | I32: 2 | J32: 6211.58 | K32: 45980 | L32: Macau - SAR of China
A33: Resort 2 | B33: 30 days pta | C33: 14276 | D33: 3569 | E33: 10707 | F33: Deposit Paid | G33: 46036 | H33: 46040 | I33: 4 | J33: 8593.64 | K33: 45947 | L33: China
A34: Resort 2 | B34: 30 days pta | C34: 28288.4 | E34: 28288.4 | F34: Not paid yet | G34: 46036 | H34: 46043 | I34: 7 | J34: 17820.46 | K34: 45902 | L34: Canada
A35: Resort 2 | B35: 30 days pta | C35: 13655.36 | D35: 11055.36 | E35: 2600 | F35: Deposit Paid | G35: 46036 | H35: 46038 | I35: 2 | J35: 8201.58 | K35: 45939 | L35: Chinese Taiwan
A36: Resort 2 | B36: 30 days pta | C36: 15446 | D36: 3861 | E36: 11585 | F36: Deposit Paid | G36: 46036 | H36: 46040 | I36: 4 | J36: 7577.84 | K36: 45969 | L36: China
A37: Resort 2 | B37: 30 days pta | C37: 102038.43 | D37: 102038.43 | F37: Fully Paid | G37: 46037 | H37: 46044 | I37: 7 | J37: 75122.46 | K37: 45980 | L37: Australia
A38: Resort 2 | B38: 30 days pta | C38: 61778.72 | D38: 9542.5 | E38: 52236.22 | F38: Deposit Paid | G38: 46037 | H38: 46044 | I38: 7 | J38: 39983.79 | K38: 45944 | L38: Australia
A39: Resort 2 | B39: 30 days pta | C39: 23095 | E39: 23095 | F39: Not paid yet | G39: 46037 | H39: 46042 | I39: 5 | J39: 0 | K39: 45984 | L39: Kazakhstan
A40: Resort 2 | G40: 46037 | H40: 46041 | I40: 4
...

Sheet Resort 3
A1: Resort | B1: Due Date | C1: Invoice Amount | D1: Payment Received | E1: Balance | F1: Payment Status | G1: Arrival | H1: Departure | I1: No of nights | J1: Opera Status | K1: Date Entered | L1: Country
A2: Resort 3 | B2: 90 days pta | C2: 0 | E2: 0 | F2: Comp | G2: 46024 | H2: 46026 | I2: 2 | J2: COG | K2: 45972 | L2: United Arab Emirates
A3: Resort 3 | B3: 90 days pta | C3: 18133.32 | D3: 18133.32 | F3: Fully Paid | G3: 46025 | H3: 46028 | I3: 3 | J3: DPR | K3: 45974 | L3: Germany
A4: Resort 3 | B4: 30 days pta | C4: 47826 | D4: 47826 | F4: Fully Paid | G4: 46034 | H4: 46036 | I4: 2 | J4: DPR | K4: 45976 | L4: Saudi Arabia
A5: Resort 3 | B5: 30 days pta | C5: 26896.8 | D5: 6724.2 | E5: 20172.6 | F5: Deposit paid | G5: 46035 | H5: 46037 | I5: 2 | J5: DPR | K5: 45957 | L5: United States
A6: Resort 3 | B6: 30 days pta | C6: 39274.86 | D6: 30664.86 | E6: 8610 | F6: Deposit paid | G6: 46035 | H6: 46038 | I6: 3 | J6: DPR | K6: 45963 | L6: United States
A7: Resort 3 | B7: 30 days pta | C7: 99261.62 | E7: 99261.62 | F7: Not paid yet | G7: 46035 | H7: 46042 | I7: 7 | J7: NOG | K7: 45859 | L7: United States
A8: Resort 3 | B8: 30 days pta | C8: 0 | E8: 0 | F8: Comp | G8: 46041 | H8: 46043 | I8: 2 | J8: COG | K8: 45954 | L8: China
A9: Resort 3 | B9: 30 days pta | C9: 62200 | D9: 62200 | F9: Fully Paid | G9: 46045 | H9: 46051 | I9: 6 | J9: DPR | K9: 45588 | L9: United States
A10: Resort 3 | B10: 30 days pta | F10: Comp | G10: 46047 | H10: 46050 | J10: TENT
A11: Resort 3 | B11: 30 days pta | C11: 50914 | E11: 50914 | F11: Not paid yet | G11: 46048 | H11: 46050 | I11: 2 | J11: TOG | K11: 45748 | L11: Japan
A12: Resort 3 | B12: 30 days pta | C12: 33377.37 | E12: 33377.37 | F12: Not paid yet | G12: 46050 | H12: 46053 | I12: 3 | J12: TENT | K12: 45988 | L12: United States
A13: Resort 3 | B13: 30 days pta | C13: 26559.98 | D13: 26559.98 | F13: Fully Paid | G13: 46052 | H13: 46059 | I13: 7 | J13: DPR | K13: 45803 | L13: Russia
A14: Resort 3 | B14: 30 days pta | C14: 3942 | E14: 3942 | F14: Not paid yet | G14: 46052 | H14: 46054 | I14: 2 | J14: COG | K14: 45939 | L14: Germany
A15: Resort 3 | B15: 30 days pta | C15: 77770.06 | D15: 15692.64 | E15: 62077.42 | F15: Deposit paid | G15: 46057 | H15: 46065 | I15: 8 | J15: DPR | K15: 45812 | L15: United States
A16: Resort 3 | B16: 30 days pta | C16: 575 | E16: 575 | F16: Payment on Arrival | G16: 46059 | H16: 46061 | I16: 2 | J16: COG | K16: 45869 | L16: Russia
A17: Resort 3 | B17: 30 days pta | C17: 18948 | D17: 5684.4 | E17: 13263.6 | F17: Deposit paid | G17: 46063 | H17: 46065 | I17: 2 | J17: DPR | K17: 45951 | L17: Brazil
A18: Resort 3 | B18: 30 days pta | C18: 0 | E18: 0 | F18: Comp | G18: 46067 | H18: 46070 | I18: 3 | J18: COG | K18: 45989 | L18: UNITED KINGDOM
A19: Resort 3 | B19: 30 days pta | C19: 21328.5 | E19: 21328.5 | F19: Not paid yet | G19: 46067 | H19: 46070 | I19: 3 | J19: NOG | K19: 45446 | L19: UNITED KINGDOM
A20: Resort 3 | B20: 30 days pta | C20: 15001.26 | E20: 15001.26 | F20: Not paid yet | G20: 46068 | H20: 46070 | I20: 2 | J20: NOG | K20: 45885 | L20: United States
A21: Resort 3 | B21: 30 days pta | C21: 36994 | D21: 9248.5 | E21: 27745.5 | F21: Deposit paid | G21: 46068 | H21: 46072 | I21: 4 | J21: DPR | K21: 45967 | L21: China
A22: Resort 3 | B22: 30 days pta | C22: 0 | E22: 0 | F22: Comp | G22: 46071 | H22: 46073 | I22: 2 | J22: COG | K22: 46001 | L22: Saudi Arabia
A23: Resort 3 | B23: 30 days pta | C23: 45555 | D23: 45555 | F23: Fully Paid | G23: 46071 | H23: 46076 | I23: 5 | J23: DPR | K23: 45972 | L23: United Arab Emirates
A24: Resort 3 | B24: 30 days pta | C24: 35046 | E24: 35046 | F24: Not paid yet | G24: 46071 | H24: 46075 | I24: 4 | J24: NOG | K24: 45989 | L24: China
A25: Resort 3 | B25: 30 days pta | C25: 3900 | D25: 3900 | F25: Fully Paid | G25: 46072 | H25: 46073 | I25: 1 | J25: DPR | K25: 45883 | L25: China
A26: Resort 3 | B26: 30 days pta | C26: 334000.04 | D26: 334000.04 | F26: Fully Paid | G26: 46077 | H26: 46091 | I26: 14 | J26: DPR | K26: 45939 | L26: United Arab Emirates
A27: Resort 3 | B27: 30 days pta | C27: 1150 | E27: 1150 | F27: Not paid yet | G27: 46086 | H27: 46087 | I27: 1 | J27: NOG | K27: 45717 | L27: UNITED KINGDOM
A28: Resort 3 | B28: 30 days pta | C28: 28270 | E28: 28270 | F28: Not paid yet | G28: 46087 | H28: 46092 | I28: 5 | J28: NOG | K28: 45877 | L28: Germany
A29: Resort 3 | B29: 30 days pta | C29: 56549.5 | E29: 56549.5 | F29: Not paid yet | G29: 46089 | H29: 46096 | I29: 7 | J29: DPR | K29: 45987 | L29: Austria
A30: Resort 3 | B30: 30 days pta | C30: 136903.07 | D30: 136903.07 | F30: Fully Paid | G30: 46096 | H30: 46110 | I30: 14 | J30: DPR | K30: 45761 | L30: Germany
A31: Resort 3 | B31: 30 days pta | C31: 56091 | E31: 56091 | F31: Not paid yet | G31: 46097 | H31: 46106 | I31: 9 | J31: NOG | K31: 45828 | L31: Germany
A32: Resort 3 | B32: 30 days pta | C32: 0 | E32: 0 | F32: Comp | G32: 46098 | H32: 46100 | I32: 2 | J32: COG | K32: 45799 | L32: United States
A33: Resort 3 | B33: 30 days pta | C33: 0 | E33: 0 | F33: Comp | G33: 46098 | H33: 46100 | I33: 2 | J33: COG | K33: 45989 | L33: UNITED KINGDOM
A34: Resort 3 | B34: 30 days pta | G34: 46099 | H34: 46104 | J34: TEN
A35: Resort 3 | B35: 30 days pta | G35: 46099 | H35: 46104 | J35: TEN
A36: Resort 3 | B36: 30 days pta | C36: 56981.2 | D36: 32227.01 | E36: 24754.19 | F36: Deposit paid | G36: 46100 | H36: 46110 | I36: 10 | J36: DPR | K36: 45775 | L36: Slovakia
A37: Resort 3 | B37: 30 days pta | C37: 91374 | E37: 91374 | F37: Not paid yet | G37: 46109 | H37: 46118 | I37: 9 | J37: NOG | K37: 45958 | L37: Spain
A38: Resort 3 | B38: 30 days pta | C38: 75860 | E38: 75860 | F38: Not paid yet | G38: 46110 | H38: 46117 | I38: 7 | J38: NOG | K38: 45800 | L38: UNITED KINGDOM
A39: Resort 3 | B39: 30 days pta | C39: 86700 | E39: 86700 | F39: Not paid yet | G39: 46110 | H39: 46117 | I39: 7 | J39: NOG | K39: 45800 | L39: UNITED KINGDOM
A40: Resort 3 | B40: 30 days pta | C40: 51524.6 | D40: 14095.89 | E40: 37428.71 | F40: Deposit paid | G40: 46112 | H40: 46117 | I40: 5 | J40: DPR | K40: 45833 | L40: UNITED KINGDOM
...
